Workbook

Sheet Control
A1: Spin Coach · Recetas de sesión
A2: Minutos programados por receta. Debe coincidir con la duración; si no, la celda se marca en rojo.
A4: Tipo | B4: 15′ | C4: 30′ | D4: 45′ | E4: 60′ | F4: Min de intervalos (60′)
A5: Continuo | B5: =SUMIFS(Recetas!$H$2:$H$119,Recetas!$B$2:$B$119,$A5,Recetas!$C$2:$C$119,15) -> 15 | C5: =SUMIFS(Recetas!$H$2:$H$119,Recetas!$B$2:$B$119,$A5,Recetas!$C$2:$C$119,30) -> 30 | D5: =SUMIFS(Recetas!$H$2:$H$119,Recetas!$B$2:$B$119,$A5,Recetas!$C$2:$C$119,45) -> 45 | E5: =SUMIFS(Recetas!$H$2:$H$119,Recetas!$B$2:$B$119,$A5,Recetas!$C$2:$C$119,60) -> 60 | F5: =SUMPRODUCT((Recetas!$B$2:$B$119=$A5)*(Recetas!$C$2:$C$119=60)*(LEFT(Recetas!$F$2:$F$119,1)="I")*Recetas!$H$2:$H$119) -> 0
A6: Progresivo | B6: =SUMIFS(Recetas!$H$2:$H$119,Recetas!$B$2:$B$119,$A6,Recetas!$C$2:$C$119,15) -> 15 | C6: =SUMIFS(Recetas!$H$2:$H$119,Recetas!$B$2:$B$119,$A6,Recetas!$C$2:$C$119,30) -> 30 | D6: =SUMIFS(Recetas!$H$2:$H$119,Recetas!$B$2:$B$119,$A6,Recetas!$C$2:$C$119,45) -> 45 | E6: =SUMIFS(Recetas!$H$2:$H$119,Recetas!$B$2:$B$119,$A6,Recetas!$C$2:$C$119,60) -> 60 | F6: =SUMPRODUCT((Recetas!$B$2:$B$119=$A6)*(Recetas!$C$2:$C$119=60)*(LEFT(Recetas!$F$2:$F$119,1)="I")*Recetas!$H$2:$H$119) -> 0
A7: HIIT | B7: =SUMIFS(Recetas!$H$2:$H$119,Recetas!$B$2:$B$119,$A7,Recetas!$C$2:$C$119,15) -> 15 | C7: =SUMIFS(Recetas!$H$2:$H$119,Recetas!$B$2:$B$119,$A7,Recetas!$C$2:$C$119,30) -> 30 | D7: =SUMIFS(Recetas!$H$2:$H$119,Recetas!$B$2:$B$119,$A7,Recetas!$C$2:$C$119,45) -> 45 | E7: =SUMIFS(Recetas!$H$2:$H$119,Recetas!$B$2:$B$119,$A7,Recetas!$C$2:$C$119,60) -> 60 | F7: =SUMPRODUCT((Recetas!$B$2:$B$119=$A7)*(Recetas!$C$2:$C$119=60)*(LEFT(Recetas!$F$2:$F$119,1)="I")*Recetas!$H$2:$H$119) -> 12
A8: Escalada | B8: =SUMIFS(Recetas!$H$2:$H$119,Recetas!$B$2:$B$119,$A8,Recetas!$C$2:$C$119,15) -> 15 | C8: =SUMIFS(Recetas!$H$2:$H$119,Recetas!$B$2:$B$119,$A8,Recetas!$C$2:$C$119,30) -> 30 | D8: =SUMIFS(Recetas!$H$2:$H$119,Recetas!$B$2:$B$119,$A8,Recetas!$C$2:$C$119,45) -> 45 | E8: =SUMIFS(Recetas!$H$2:$H$119,Recetas!$B$2:$B$119,$A8,Recetas!$C$2:$C$119,60) -> 60 | F8: =SUMPRODUCT((Recetas!$B$2:$B$119=$A8)*(Recetas!$C$2:$C$119=60)*(LEFT(Recetas!$F$2:$F$119,1)="I")*Recetas!$H$2:$H$119) -> 0
A11: Cómo editar
A12: • Texto azul = datos que puedes cambiar (bloque, minutos, fase, notas). Verde = calculado desde la hoja Bloques; no editar.
A13: • Filas en amarillo = dudas abiertas para decidir (ahora mismo ninguna).
A14: • Para cambiar rueda, RPM o BPM de un tipo de bloque, edítalo en la hoja Bloques y se propaga a todas las recetas.
A15: • Ejemplo de fila: HIIT · 45 · orden 4 · Serie 1 · I30 · 4 min → intervalos 30/30 de 4′ a 100–110 RPM.
A17: Reglas de diseño
A18: • Una sesión es una receta de fases: calentamiento + fases del catálogo + calma.
A19: • Bloque mínimo de 3′ (≈ 1 canción). Los intervalos cortos van dentro de un bloque y los marca la voz del coach.
A20: • HIIT: bloque de series casi fijo (máx. 3 series de ~7′); el tiempo extra va a activación y apoyo, no a más series.
A21: • HIIT: sesiones cortas con Tabata 20/10; en las largas, escalera 30/30 → 40/20 → 20/10.
A22: • Escalada: la última subida es siempre el remate (rueda 8-9, la que pueda cada uno).
A23: • Activación previa a HIIT/Escalada: llano → tempo (Z2–Z3), nunca Z4.
... A25: • Cobertura musical: se comprueba siempre contra la receta de 60′ de cada tipo; si no se cubre, se amplía con Last.fm.

Sheet Bloques
A1: ID | B1: Bloque | C1: Posición | D1: Rueda mín | E1: Rueda máx | F1: RPM mín | G1: RPM máx | H1: Relación música | I1: Factor BPM | J1: BPM mín | K1: BPM máx | L1: Zona | M1: Indicación tipo del coach
A2: CAL | B2: Calentamiento | C2: Sentado | D2: 2 | E2: 3 | F2: 85 | G2: 95 | H2: 1:1 | I2: 1 | J2: =F2*I2 -> 85 | K2: =G2*I2 -> 95 | L2: Z1 | M2: Rueda suave, busca el ritmo de la música
A3: LLA | B3: Llano | C3: Sentado | D3: 3 | E3: 4 | F3: 90 | G3: 100 | H3: 1:1 | I3: 1 | J3: =F3*I3 -> 90 | K3: =G3*I3 -> 100 | L3: Z2 | M3: Ritmo cómodo, una pedalada por golpe
A4: TEM | B4: Tempo | C4: Sentado | D4: 5 | E4: 6 | F4: 90 | G4: 100 | H4: 1:1 | I4: 1 | J4: =F4*I4 -> 90 | K4: =G4*I4 -> 100 | L4: Z3 | M4: Sube un punto de rueda y mantén la cadencia
A5: SSU | B5: Subida suave | C5: Sentado | D5: 5 | E5: 6 | F5: 75 | G5: 85 | H5: ½ tempo | I5: 2 | J5: =F5*I5 -> 150 | K5: =G5*I5 -> 170 | L5: Z3 | M5: Un poco de rueda, sin apretar: subida de fondo
A6: SUS | B6: Subida sentado | C6: Sentado | D6: 6 | E6: 7 | F6: 70 | G6: 80 | H6: ½ tempo | I6: 2 | J6: =F6*I6 -> 140 | K6: =G6*I6 -> 160 | L6: Z4 | M6: Carga rueda, pedalada larga cada dos golpes
A7: SUP | B7: Subida de pie | C7: De pie | D7: 7 | E7: 8 | F7: 60 | G7: 75 | H7: ½ tempo | I7: 2 | J7: =F7*I7 -> 120 | K7: =G7*I7 -> 150 | L7: Z4 | M7: ¡Arriba! Peso sobre los pedales, cada dos golpes
A8: SUR | B8: Subida de pie (remate) | C8: De pie | D8: 8 | E8: 9 | F8: 60 | G8: 70 | H8: ½ tempo | I8: 2 | J8: =F8*I8 -> 120 | K8: =G8*I8 -> 140 | L8: Z5 | M8: Última subida: rueda 8 o 9, la que puedas
A9: I30 | B9: Intervalos 30/30 | C9: Sentado / de pie | D9: 6 | E9: 7 | F9: 100 | G9: 110 | H9: 1:1 | I9: 1 | J9: =F9*I9 -> 100 | K9: =G9*I9 -> 110 | L9: Z4 | M9: 30 s fuerte, 30 s suelta. El coach cuenta cada cambio
A10: I40 | B10: Intervalos 40/20 | C10: Sentado / de pie | D10: 6 | E10: 8 | F10: 100 | G10: 115 | H10: 1:1 | I10: 1 | J10: =F10*I10 -> 100 | K10: =G10*I10 -> 115 | L10: Z5 | M10: 40 s a tope, 20 s suelta. El coach cuenta cada cambio
A11: I20 | B11: Intervalos 20/10 (Tabata) | C11: Sentado / de pie | D11: 7 | E11: 9 | F11: 105 | G11: 120 | H11: 1:1 | I11: 1 | J11: =F11*I11 -> 105 | K11: =G11*I11 -> 120 | L11: Z5 | M11: 20 s al máximo, 10 s de respiro. 6 rondas en 3′, 8 en 4′
A12: SPR | B12: Sprint | C12: Sentado | D12: 5 | E12: 6 | F12: 100 | G12: 120 | H12: 1:1 | I12: 1 | J12: =F12*I12 -> 100 | K12: =G12*I12 -> 120 | L12: Z5 | M12: Todo lo que tengas, rueda media
A13: REC | B13: Recuperación | C13: Sentado | D13: 2 | E13: 3 | F13: 80 | G13: 90 | H13: 1:1 | I13: 1 | J13: =F13*I13 -> 80 | K13: =G13*I13 -> 90 | L13: Z1 | M13: Suelta rueda, respira
A14: CLM | B14: Vuelta a la calma | C14: Sentado | D14: 1 | E14: 2 | F14: 70 | G14: 90 | H14: Suave | I14: 1 | J14: =F14*I14 -> 70 | K14: =G14*I14 -> 90 | L14: Z1 | M14: Baja pulsaciones, estira la espalda

Sheet Recetas
A1: Receta | B1: Tipo | C1: Duración (min) | D1: Orden | E1: Fase | F1: ID bloque | G1: Bloque | H1: Min | I1: Inicio (min) | J1: Posición | K1: Rueda | L1: RPM | M1: BPM música | N1: Notas / dudas
A2: =B2&" "&C2&"′" -> Continuo 15′ | B2: Continuo | C2: 15 | D2: 1 | E2: Calentamiento | F2: CAL | G2: =INDEX(Bloques!$B$2:$B$20,MATCH($F2,Bloques!$A$2:$A$20,0)) -> Calentamiento | H2: 4 | I2: 0 | J2: =INDEX(Bloques!$C$2:$C$20,MATCH($F2,Bloques!$A$2:$A$20,0)) -> Sentado | K2: =INDEX(Bloques!$D$2:$D$20,MATCH($F2,Bloques!$A$2:$A$20,0))&"–"&INDEX(Bloques!$E$2:$E$20,MATCH($F2,Bloques!$A$2:$A$20,0)) -> 2–3 | L2: =INDEX(Bloques!$F$2:$F$20,MATCH($F2,Bloques!$A$2:$A$20,0))&"–"&INDEX(Bloques!$G$2:$G$20,MATCH($F2,Bloques!$A$2:$A$20,0)) -> 85–95 | M2: =INDEX(Bloques!$J$2:$J$20,MATCH($F2,Bloques!$A$2:$A$20,0))&"–"&INDEX(Bloques!$K$2:$K$20,MATCH($F2,Bloques!$A$2:$A$20,0)) -> 85–95
A3: =B3&" "&C3&"′" -> Continuo 15′ | B3: Continuo | C3: 15 | D3: 2 | E3: Base | F3: LLA | G3: =INDEX(Bloques!$B$2:$B$20,MATCH($F3,Bloques!$A$2:$A$20,0)) -> Llano | H3: 4 | I3: =I2+H2 -> 4 | J3: =INDEX(Bloques!$C$2:$C$20,MATCH($F3,Bloques!$A$2:$A$20,0)) -> Sentado | K3: =INDEX(Bloques!$D$2:$D$20,MATCH($F3,Bloques!$A$2:$A$20,0))&"–"&INDEX(Bloques!$E$2:$E$20,MATCH($F3,Bloques!$A$2:$A$20,0)) -> 3–4 | L3: =INDEX(Bloques!$F$2:$F$20,MATCH($F3,Bloques!$A$2:$A$20,0))&"–"&INDEX(Bloques!$G$2:$G$20,MATCH($F3,Bloques!$A$2:$A$20,0)) -> 90–100 | M3: =INDEX(Bloques!$J$2:$J$20,MATCH($F3,Bloques!$A$2:$A$20,0))&"–"&INDEX(Bloques!$K$2:$K$20,MATCH($F3,Bloques!$A$2:$A$20,0)) -> 90–100
A4: =B4&" "&C4&"′" -> Continuo 15′ | B4: Continuo | C4: 15 | D4: 3 | E4: Ondulación | F4: TEM | G4: =INDEX(Bloques!$B$2:$B$20,MATCH($F4,Bloques!$A$2:$A$20,0)) -> Tempo | H4: 4 | I4: =I3+H3 -> 8 | J4: =INDEX(Bloques!$C$2:$C$20,MATCH($F4,Bloques!$A$2:$A$20,0)) -> Sentado | K4: =INDEX(Bloques!$D$2:$D$20,MATCH($F4,Bloques!$A$2:$A$20,0))&"–"&INDEX(Bloques!$E$2:$E$20,MATCH($F4,Bloques!$A$2:$A$20,0)) -> 5–6 | L4: =INDEX(Bloques!$F$2:$F$20,MATCH($F4,Bloques!$A$2:$A$20,0))&"–"&INDEX(Bloques!$G$2:$G$20,MATCH($F4,Bloques!$A$2:$A$20,0)) -> 90–100 | M4: =INDEX(Bloques!$J$2:$J$20,MATCH($F4,Bloques!$A$2:$A$20,0))&"–"&INDEX(Bloques!$K$2:$K$20,MATCH($F4,Bloques!$A$2:$A$20,0)) -> 90–100
A5: =B5&" "&C5&"′" -> Continuo 15′ | B5: Continuo | C5: 15 | D5: 4 | E5: Calma | F5: CLM | G5: =INDEX(Bloques!$B$2:$B$20,MATCH($F5,Bloques!$A$2:$A$20,0)) -> Vuelta a la calma | H5: 3 | I5: =I4+H4 -> 12 | J5: =INDEX(Bloques!$C$2:$C$20,MATCH($F5,Bloques!$A$2:$A$20,0)) -> Sentado | K5: =INDEX(Bloques!$D$2:$D$20,MATCH($F5,Bloques!$A$2:$A$20,0))&"–"&INDEX(Bloques!$E$2:$E$20,MATCH($F5,Bloques!$A$2:$A$20,0)) -> 1–2 | L5: =INDEX(Bloques!$F$2:$F$20,MATCH($F5,Bloques!$A$2:$A$20,0))&"–"&INDEX(Bloques!$G$2:$G$20,MATCH($F5,Bloques!$A$2:$A$20,0)) -> 70–90 | M5: =INDEX(Bloques!$J$2:$J$20,MATCH($F5,Bloques!$A$2:$A$20,0))&"–"&INDEX(Bloques!$K$2:$K$20,MATCH($F5,Bloques!$A$2:$A$20,0)) -> 70–90
A6: =B6&" "&C6&"′" -> Continuo 30′ | B6: Continuo | C6: 30 | D6: 1 | E6: Calentamiento | F6: CAL | G6: =INDEX(Bloques!$B$2:$B$20,MATCH($F6,Bloques!$A$2:$A$20,0)) -> Calentamiento | H6: 6 | I6: 0 | J6: =INDEX(Bloques!$C$2:$C$20,MATCH($F6,Bloques!$A$2:$A$20,0)) -> Sentado | K6: =INDEX(Bloques!$D$2:$D$20,MATCH($F6,Bloques!$A$2:$A$20,0))&"–"&INDEX(Bloques!$E$2:$E$20,MATCH($F6,Bloques!$A$2:$A$20,0)) -> 2–3 | L6: =INDEX(Bloques!$F$2:$F$20,MATCH($F6,Bloques!$A$2:$A$20,0))&"–"&INDEX(Bloques!$G$2:$G$20,MATCH($F6,Bloques!$A$2:$A$20,0)) -> 85–95 | M6: =INDEX(Bloques!$J$2:$J$20,MATCH($F6,Bloques!$A$2:$A$20,0))&"–"&INDEX(Bloques!$K$2:$K$20,MATCH($F6,Bloques!$A$2:$A$20,0)) -> 85–95
A7: =B7&" "&C7&"′" -> Continuo 30′ | B7: Continuo | C7: 30 | D7: 2 | E7: Ciclo 1 | F7: LLA | G7: =INDEX(Bloques!$B$2:$B$20,MATCH($F7,Bloques!$A$2:$A$20,0)) -> Llano | H7: 6 | I7: =I6+H6 -> 6 | J7: =INDEX(Bloques!$C$2:$C$20,MATCH($F7,Bloques!$A$2:$A$20,0)) -> Sentado | K7: =INDEX(Bloques!$D$2:$D$20,MATCH($F7,Bloques!$A$2:$A$20,0))&"–"&INDEX(Bloques!$E$2:$E$20,MATCH($F7,Bloques!$A$2:$A$20,0)) -> 3–4 | L7: =INDEX(Bloques!$F$2:$F$20,MATCH($F7,Bloques!$A$2:$A$20,0))&"–"&INDEX(Bloques!$G$2:$G$20,MATCH($F7,Bloques!$A$2:$A$20,0)) -> 90–100 | M7: =INDEX(Bloques!$J$2:$J$20,MATCH($F7,Bloques!$A$2:$A$20,0))&"–"&INDEX(Bloques!$K$2:$K$20,MATCH($F7,Bloques!$A$2:$A$20,0)) -> 90–100
A8: =B8&" "&C8&"′" -> Continuo 30′ | B8: Continuo | C8: 30 | D8: 3 | E8: Ciclo 1 | F8: TEM | G8: =INDEX(Bloques!$B$2:$B$20,MATCH($F8,Bloques!$A$2:$A$20,0)) -> Tempo | H8: 4 | I8: =I7+H7 -> 12 | J8: =INDEX(Bloques!$C$2:$C$20,MATCH($F8,Bloques!$A$2:$A$20,0)) -> Sentado | K8: =INDEX(Bloques!$D$2:$D$20,MATCH($F8,Bloques!$A$2:$A$20,0))&"–"&INDEX(Bloques!$E$2:$E$20,MATCH($F8,Bloques!$A$2:$A$20,0)) -> 5–6 | L8: =INDEX(Bloques!$F$2:$F$20,MATCH($F8,Bloques!$A$2:$A$20,0))&"–"&INDEX(Bloques!$G$2:$G$20,MATCH($F8,Bloques!$A$2:$A$20,0)) -> 90–100 | M8: =INDEX(Bloques!$J$2:$J$20,MATCH($F8,Bloques!$A$2:$A$20,0))&"–"&INDEX(Bloques!$K$2:$K$20,MATCH($F8,Bloques!$A$2:$A$20,0)) -> 90–100
A9: =B9&" "&C9&"′" -> Continuo 30′ | B9: Continuo | C9: 30 | D9: 4 | E9: Ciclo 2 | F9: LLA | G9: =INDEX(Bloques!$B$2:$B$20,MATCH($F9,Bloques!$A$2:$A$20,0)) -> Llano | H9: 5 | I9: =I8+H8 -> 16 | J9: =INDEX(Bloques!$C$2:$C$20,MATCH($F9,Bloques!$A$2:$A$20,0)) -> Sentado | K9: =INDEX(Bloques!$D$2:$D$20,MATCH($F9,Bloques!$A$2:$A$20,0))&"–"&INDEX(Bloques!$E$2:$E$20,MATCH($F9,Bloques!$A$2:$A$20,0)) -> 3–4 | L9: =INDEX(Bloques!$F$2:$F$20,MATCH($F9,Bloques!$A$2:$A$20,0))&"–"&INDEX(Bloques!$G$2:$G$20,MATCH($F9,Bloques!$A$2:$A$20,0)) -> 90–100 | M9: =INDEX(Bloques!$J$2:$J$20,MATCH($F9,Bloques!$A$2:$A$20,0))&"–"&INDEX(Bloques!$K$2:$K$20,MATCH($F9,Bloques!$A$2:$A$20,0)) -> 90–100
A10: =B10&" "&C10&"′" -> Continuo 30′ | B10: Continuo | C10: 30 | D10: 5 | E10: Ciclo 2 | F10: SSU | G10: =INDEX(Bloques!$B$2:$B$20,MATCH($F10,Bloques!$A$2:$A$20,0)) -> Subida suave | H10: 4 | I10: =I9+H9 -> 21 | J10: =INDEX(Bloques!$C$2:$C$20,MATCH($F10,Bloques!$A$2:$A$20,0)) -> Sentado | K10: =INDEX(Bloques!$D$2:$D$20,MATCH($F10,Bloques!$A$2:$A$20,0))&"–"&INDEX(Bloques!$E$2:$E$20,MATCH($F10,Bloques!$A$2:$A$20,0)) -> 5–6 | L10: =INDEX(Bloques!$F$2:$F$20,MATCH($F10,Bloques!$A$2:$A$20,0))&"–"&INDEX(Bloques!$G$2:$G$20,MATCH($F10,Bloques!$A$2:$A$20,0)) -> 75–85 | M10: =INDEX(Bloques!$J$2:$J$20,MATCH($F10,Bloques!$A$2:$A$20,0))&"–"&INDEX(Bloques!$K$2:$K$20,MATCH($F10,Bloques!$A$2:$A$20,0)) -> 150–170
A11: =B11&" "&C11&"′" -> Continuo 30′ | B11: Continuo | C11: 30 | D11: 6 | E11: Calma | F11: CLM | G11: =INDEX(Bloques!$B$2:$B$20,MATCH($F11,Bloques!$A$2:$A$20,0)) -> Vuelta a la calma | H11: 5 | I11: =I10+H10 -> 25 | J11: =INDEX(Bloques!$C$2:$C$20,MATCH($F11,Bloques!$A$2:$A$20,0)) -> Sentado | K11: =INDEX(Bloques!$D$2:$D$20,MATCH($F11,Bloques!$A$2:$A$20,0))&"–"&INDEX(Bloques!$E$2:$E$20,MATCH($F11,Bloques!$A$2:$A$20,0)) -> 1–2 | L11: =INDEX(Bloques!$F$2:$F$20,MATCH($F11,Bloques!$A$2:$A$20,0))&"–"&INDEX(Bloques!$G$2:$G$20,MATCH($F11,Bloques!$A$2:$A$20,0)) -> 70–90 | M11: =INDEX(Bloques!$J$2:$J$20,MATCH($F11,Bloques!$A$2:$A$20,0))&"–"&INDEX(Bloques!$K$2:$K$20,MATCH($F11,Bloques!$A$2:$A$20,0)) -> 70–90
A12: =B12&" "&C12&"′" -> Continuo 45′ | B12: Continuo | C12: 45 | D12: 1 | E12: Calentamiento | F12: CAL | G12: =INDEX(Bloques!$B$2:$B$20,MATCH($F12,Bloques!$A$2:$A$20,0)) -> Calentamiento | H12: 8 | I12: 0 | J12: =INDEX(Bloques!$C$2:$C$20,MATCH($F12,Bloques!$A$2:$A$20,0)) -> Sentado | K12: =INDEX(Bloques!$D$2:$D$20,MATCH($F12,Bloques!$A$2:$A$20,0))&"–"&INDEX(Bloques!$E$2:$E$20,MATCH($F12,Bloques!$A$2:$A$20,0)) -> 2–3 | L12: =INDEX(Bloques!$F$2:$F$20,MATCH($F12,Bloques!$A$2:$A$20,0))&"–"&INDEX(Bloques!$G$2:$G$20,MATCH($F12,Bloques!$A$2:$A$20,0)) -> 85–95 | M12: =INDEX(Bloques!$J$2:$J$20,MATCH($F12,Bloques!$A$2:$A$20,0))&"–"&INDEX(Bloques!$K$2:$K$20,MATCH($F12,Bloques!$A$2:$A$20,0)) -> 85–95
A13: =B13&" "&C13&"′" -> Continuo 45′ | B13: Continuo | C13: 45 | D13: 2 | E13: Ciclo 1 | F13: LLA | G13: =INDEX(Bloques!$B$2:$B$20,MATCH($F13,Bloques!$A$2:$A$20,0)) -> Llano | H13: 7 | I13: =I12+H12 -> 8 | J13: =INDEX(Bloques!$C$2:$C$20,MATCH($F13,Bloques!$A$2:$A$20,0)) -> Sentado | K13: =INDEX(Bloques!$D$2:$D$20,MATCH($F13,Bloques!$A$2:$A$20,0))&"–"&INDEX(Bloques!$E$2:$E$20,MATCH($F13,Bloques!$A$2:$A$20,0)) -> 3–4 | L13: =INDEX(Bloques!$F$2:$F$20,MATCH($F13,Bloques!$A$2:$A$20,0))&"–"&INDEX(Bloques!$G$2:$G$20,MATCH($F13,Bloques!$A$2:$A$20,0)) -> 90–100 | M13: =INDEX(Bloques!$J$2:$J$20,MATCH($F13,Bloques!$A$2:$A$20,0))&"–"&INDEX(Bloques!$K$2:$K$20,MATCH($F13,Bloques!$A$2:$A$20,0)) -> 90–100
A14: =B14&" "&C14&"′" -> Continuo 45′ | B14: Continuo | C14: 45 | D14: 3 | E14: Ciclo 1 | F14: TEM | G14: =INDEX(Bloques!$B$2:$B$20,MATCH($F14,Bloques!$A$2:$A$20,0)) -> Tempo | H14: 5 | I14: =I13+H13 -> 15 | J14: =INDEX(Bloques!$C$2:$C$20,MATCH($F14,Bloques!$A$2:$A$20,0)) -> Sentado | K14: =INDEX(Bloques!$D$2:$D$20,MATCH($F14,Bloques!$A$2:$A$20,0))&"–"&INDEX(Bloques!$E$2:$E$20,MATCH($F14,Bloques!$A$2:$A$20,0)) -> 5–6 | L14: =INDEX(Bloques!$F$2:$F$20,MATCH($F14,Bloques!$A$2:$A$20,0))&"–"&INDEX(Bloques!$G$2:$G$20,MATCH($F14,Bloques!$A$2:$A$20,0)) -> 90–100 | M14: =INDEX(Bloques!$J$2:$J$20,MATCH($F14,Bloques!$A$2:$A$20,0))&"–"&INDEX(Bloques!$K$2:$K$20,MATCH($F14,Bloques!$A$2:$A$20,0)) -> 90–100
A15: =B15&" "&C15&"′" -> Continuo 45′ | B15: Continuo | C15: 45 | D15: 4 | E15: Ciclo 2 | F15: LLA | G15: =INDEX(Bloques!$B$2:$B$20,MATCH($F15,Bloques!$A$2:$A$20,0)) -> Llano | H15: 6 | I15: =I14+H14 -> 20 | J15: =INDEX(Bloques!$C$2:$C$20,MATCH($F15,Bloques!$A$2:$A$20,0)) -> Sentado | K15: =INDEX(Bloques!$D$2:$D$20,MATCH($F15,Bloques!$A$2:$A$20,0))&"–"&INDEX(Bloques!$E$2:$E$20,MATCH($F15,Bloques!$A$2:$A$20,0)) -> 3–4 | L15: =INDEX(Bloques!$F$2:$F$20,MATCH($F15,Bloques!$A$2:$A$20,0))&"–"&INDEX(Bloques!$G$2:$G$20,MATCH($F15,Bloques!$A$2:$A$20,0)) -> 90–100 | M15: =INDEX(Bloques!$J$2:$J$20,MATCH($F15,Bloques!$A$2:$A$20,0))&"–"&INDEX(Bloques!$K$2:$K$20,MATCH($F15,Bloques!$A$2:$A$20,0)) -> 90–100
A16: =B16&" "&C16&"′" -> Continuo 45′ | B16: Continuo | C16: 45 | D16: 5 | E16: Ciclo 2 | F16: SSU | G16: =INDEX(Bloques!$B$2:$B$20,MATCH($F16,Bloques!$A$2:$A$20,0)) -> Subida suave | H16: 5 | I16: =I15+H15 -> 26 | J16: =INDEX(Bloques!$C$2:$C$20,MATCH($F16,Bloques!$A$2:$A$20,0)) -> Sentado | K16: =INDEX(Bloques!$D$2:$D$20,MATCH($F16,Bloques!$A$2:$A$20,0))&"–"&INDEX(Bloques!$E$2:$E$20,MATCH($F16,Bloques!$A$2:$A$20,0)) -> 5–6 | L16: =INDEX(Bloques!$F$2:$F$20,MATCH($F16,Bloques!$A$2:$A$20,0))&"–"&INDEX(Bloques!$G$2:$G$20,MATCH($F16,Bloques!$A$2:$A$20,0)) -> 75–85 | M16: =INDEX(Bloques!$J$2:$J$20,MATCH($F16,Bloques!$A$2:$A$20,0))&"–"&INDEX(Bloques!$K$2:$K$20,MATCH($F16,Bloques!$A$2:$A$20,0)) -> 150–170
A17: =B17&" "&C17&"′" -> Continuo 45′ | B17: Continuo | C17: 45 | D17: 6 | E17: Ciclo 3 | F17: LLA | G17: =INDEX(Bloques!$B$2:$B$20,MATCH($F17,Bloques!$A$2:$A$20,0)) -> Llano | H17: 5 | I17: =I16+H16 -> 31 | J17: =INDEX(Bloques!$C$2:$C$20,MATCH($F17,Bloques!$A$2:$A$20,0)) -> Sentado | K17: =INDEX(Bloques!$D$2:$D$20,MATCH($F17,Bloques!$A$2:$A$20,0))&"–"&INDEX(Bloques!$E$2:$E$20,MATCH($F17,Bloques!$A$2:$A$20,0)) -> 3–4 | L17: =INDEX(Bloques!$F$2:$F$20,MATCH($F17,Bloques!$A$2:$A$20,0))&"–"&INDEX(Bloques!$G$2:$G$20,MATCH($F17,Bloques!$A$2:$A$20,0)) -> 90–100 | M17: =INDEX(Bloques!$J$2:$J$20,MATCH($F17,Bloques!$A$2:$A$20,0))&"–"&INDEX(Bloques!$K$2:$K$20,MATCH($F17,Bloques!$A$2:$A$20,0)) -> 90–100
A18: =B18&" "&C18&"′" -> Continuo 45′ | B18: Continuo | C18: 45 | D18: 7 | E18: Ciclo 3 | F18: TEM | G18: =INDEX(Bloques!$B$2:$B$20,MATCH($F18,Bloques!$A$2:$A$20,0)) -> Tempo | H18: 4 | I18: =I17+H17 -> 36 | J18: =INDEX(Bloques!$C$2:$C$20,MATCH($F18,Bloques!$A$2:$A$20,0)) -> Sentado | K18: =INDEX(Bloques!$D$2:$D$20,MATCH($F18,Bloques!$A$2:$A$20,0))&"–"&INDEX(Bloques!$E$2:$E$20,MATCH($F18,Bloques!$A$2:$A$20,0)) -> 5–6 | L18: =INDEX(Bloques!$F$2:$F$20,MATCH($F18,Bloques!$A$2:$A$20,0))&"–"&INDEX(Bloques!$G$2:$G$20,MATCH($F18,Bloques!$A$2:$A$20,0)) -> 90–100 | M18: =INDEX(Bloques!$J$2:$J$20,MATCH($F18,Bloques!$A$2:$A$20,0))&"–"&INDEX(Bloques!$K$2:$K$20,MATCH($F18,Bloques!$A$2:$A$20,0)) -> 90–100
A19: =B19&" "&C19&"′" -> Continuo 45′ | B19: Continuo | C19: 45 | D19: 8 | E19: Calma | F19: CLM | G19: =INDEX(Bloques!$B$2:$B$20,MATCH($F19,Bloques!$A$2:$A$20,0)) -> Vuelta a la calma | H19: 5 | I19: =I18+H18 -> 40 | J19: =INDEX(Bloques!$C$2:$C$20,MATCH($F19,Bloques!$A$2:$A$20,0)) -> Sentado | K19: =INDEX(Bloques!$D$2:$D$20,MATCH($F19,Bloques!$A$2:$A$20,0))&"–"&INDEX(Bloques!$E$2:$E$20,MATCH($F19,Bloques!$A$2:$A$20,0)) -> 1–2 | L19: =INDEX(Bloques!$F$2:$F$20,MATCH($F19,Bloques!$A$2:$A$20,0))&"–"&INDEX(Bloques!$G$2:$G$20,MATCH($F19,Bloques!$A$2:$A$20,0)) -> 70–90 | M19: =INDEX(Bloques!$J$2:$J$20,MATCH($F19,Bloques!$A$2:$A$20,0))&"–"&INDEX(Bloques!$K$2:$K$20,MATCH($F19,Bloques!$A$2:$A$20,0)) -> 70–90
A20: =B20&" "&C20&"′" -> Continuo 60′ | B20: Continuo | C20: 60 | D20: 1 | E20: Calentamiento | F20: CAL | G20: =INDEX(Bloques!$B$2:$B$20,MATCH($F20,Bloques!$A$2:$A$20,0)) -> Calentamiento | H20: 8 | I20: 0 | J20: =INDEX(Bloques!$C$2:$C$20,MATCH($F20,Bloques!$A$2:$A$20,0)) -> Sentado | K20: =INDEX(Bloques!$D$2:$D$20,MATCH($F20,Bloques!$A$2:$A$20,0))&"–"&INDEX(Bloques!$E$2:$E$20,MATCH($F20,Bloques!$A$2:$A$20,0)) -> 2–3 | L20: =INDEX(Bloques!$F$2:$F$20,MATCH($F20,Bloques!$A$2:$A$20,0))&"–"&INDEX(Bloques!$G$2:$G$20,MATCH($F20,Bloques!$A$2:$A$20,0)) -> 85–95 | M20: =INDEX(Bloques!$J$2:$J$20,MATCH($F20,Bloques!$A$2:$A$20,0))&"–"&INDEX(Bloques!$K$2:$K$20,MATCH($F20,Bloques!$A$2:$A$20,0)) -> 85–95
A21: =B21&" "&C21&"′" -> Continuo 60′ | B21: Continuo | C21: 60 | D21: 2 | E21: Ciclo 1 | F21: LLA | G21: =INDEX(Bloques!$B$2:$B$20,MATCH($F21,Bloques!$A$2:$A$20,0)) -> Llano | H21: 8 | I21: =I20+H20 -> 8 | J21: =INDEX(Bloques!$C$2:$C$20,MATCH($F21,Bloques!$A$2:$A$20,0)) -> Sentado | K21: =INDEX(Bloques!$D$2:$D$20,MATCH($F21,Bloques!$A$2:$A$20,0))&"–"&INDEX(Bloques!$E$2:$E$20,MATCH($F21,Bloques!$A$2:$A$20,0)) -> 3–4 | L21: =INDEX(Bloques!$F$2:$F$20,MATCH($F21,Bloques!$A$2:$A$20,0))&"–"&INDEX(Bloques!$G$2:$G$20,MATCH($F21,Bloques!$A$2:$A$20,0)) -> 90–100 | M21: =INDEX(Bloques!$J$2:$J$20,MATCH($F21,Bloques!$A$2:$A$20,0))&"–"&INDEX(Bloques!$K$2:$K$20,MATCH($F21,Bloques!$A$2:$A$20,0)) -> 90–100
A22: =B22&" "&C22&"′" -> Continuo 60′ | B22: Continuo | C22: 60 | D22: 3 | E22: Ciclo 1 | F22: TEM | G22: =INDEX(Bloques!$B$2:$B$20,MATCH($F22,Bloques!$A$2:$A$20,0)) -> Tempo | H22: 6 | I22: =I21+H21 -> 16 | J22: =INDEX(Bloques!$C$2:$C$20,MATCH($F22,Bloques!$A$2:$A$20,0)) -> Sentado | K22: =INDEX(Bloques!$D$2:$D$20,MATCH($F22,Bloques!$A$2:$A$20,0))&"–"&INDEX(Bloques!$E$2:$E$20,MATCH($F22,Bloques!$A$2:$A$20,0)) -> 5–6 | L22: =INDEX(Bloques!$F$2:$F$20,MATCH($F22,Bloques!$A$2:$A$20,0))&"–"&INDEX(Bloques!$G$2:$G$20,MATCH($F22,Bloques!$A$2:$A$20,0)) -> 90–100 | M22: =INDEX(Bloques!$J$2:$J$20,MATCH($F22,Bloques!$A$2:$A$20,0))&"–"&INDEX(Bloques!$K$2:$K$20,MATCH($F22,Bloques!$A$2:$A$20,0)) -> 90–100
A23: =B23&" "&C23&"′" -> Continuo 60′ | B23: Continuo | C23: 60 | D23: 4 | E23: Ciclo 2 | F23: LLA | G23: =INDEX(Bloques!$B$2:$B$20,MATCH($F23,Bloques!$A$2:$A$20,0)) -> Llano | H23: 8 | I23: =I22+H22 -> 22 | J23: =INDEX(Bloques!$C$2:$C$20,MATCH($F23,Bloques!$A$2:$A$20,0)) -> Sentado | K23: =INDEX(Bloques!$D$2:$D$20,MATCH($F23,Bloques!$A$2:$A$20,0))&"–"&INDEX(Bloques!$E$2:$E$20,MATCH($F23,Bloques!$A$2:$A$20,0)) -> 3–4 | L23: =INDEX(Bloques!$F$2:$F$20,MATCH($F23,Bloques!$A$2:$A$20,0))&"–"&INDEX(Bloques!$G$2:$G$20,MATCH($F23,Bloques!$A$2:$A$20,0)) -> 90–100 | M23: =INDEX(Bloques!$J$2:$J$20,MATCH($F23,Bloques!$A$2:$A$20,0))&"–"&INDEX(Bloques!$K$2:$K$20,MATCH($F23,Bloques!$A$2:$A$20,0)) -> 90–100
A24: =B24&" "&C24&"′" -> Continuo 60′ | B24: Continuo | C24: 60 | D24: 5 | E24: Ciclo 2 | F24: SSU | G24: =INDEX(Bloques!$B$2:$B$20,MATCH($F24,Bloques!$A$2:$A$20,0)) -> Subida suave | H24: 6 | I24: =I23+H23 -> 30 | J24: =INDEX(Bloques!$C$2:$C$20,MATCH($F24,Bloques!$A$2:$A$20,0)) -> Sentado | K24: =INDEX(Bloques!$D$2:$D$20,MATCH($F24,Bloques!$A$2:$A$20,0))&"–"&INDEX(Bloques!$E$2:$E$20,MATCH($F24,Bloques!$A$2:$A$20,0)) -> 5–6 | L24: =INDEX(Bloques!$F$2:$F$20,MATCH($F24,Bloques!$A$2:$A$20,0))&"–"&INDEX(Bloques!$G$2:$G$20,MATCH($F24,Bloques!$A$2:$A$20,0)) -> 75–85 | M24: =INDEX(Bloques!$J$2:$J$20,MATCH($F24,Bloques!$A$2:$A$20,0))&"–"&INDEX(Bloques!$K$2:$K$20,MATCH($F24,Bloques!$A$2:$A$20,0)) -> 150–170 | N24: Subida suave: rueda 5-6, sin apretar
A25: =B25&" "&C25&"′" -> Continuo 60′ | B25: Continuo | C25: 60 | D25: 6 | E25: Ciclo 3 | F25: LLA | G25: =INDEX(Bloques!$B$2:$B$20,MATCH($F25,Bloques!$A$2:$A$20,0)) -> Llano | H25: 8 | I25: =I24+H24 -> 36 | J25: =INDEX(Bloques!$C$2:$C$20,MATCH($F25,Bloques!$A$2:$A$20,0)) -> Sentado | K25: =INDEX(Bloques!$D$2:$D$20,MATCH($F25,Bloques!$A$2:$A$20,0))&"–"&INDEX(Bloques!$E$2:$E$20,MATCH($F25,Bloques!$A$2:$A$20,0)) -> 3–4 | L25: =INDEX(Bloques!$F$2:$F$20,MATCH($F25,Bloques!$A$2:$A$20,0))&"–"&INDEX(Bloques!$G$2:$G$20,MATCH($F25,Bloques!$A$2:$A$20,0)) -> 90–100 | M25: =INDEX(Bloques!$J$2:$J$20,MATCH($F25,Bloques!$A$2:$A$20,0))&"–"&INDEX(Bloques!$K$2:$K$20,MATCH($F25,Bloques!$A$2:$A$20,0)) -> 90–100
A26: =B26&" "&C26&"′" -> Continuo 60′ | B26: Continuo | C26: 60 | D26: 7 | E26: Ciclo 3 | F26: TEM | G26: =INDEX(Bloques!$B$2:$B$20,MATCH($F26,Bloques!$A$2:$A$20,0)) -> Tempo | H26: 6 | I26: =I25+H25 -> 44 | J26: =INDEX(Bloques!$C$2:$C$20,MATCH($F26,Bloques!$A$2:$A$20,0)) -> Sentado | K26: =INDEX(Bloques!$D$2:$D$20,MATCH($F26,Bloques!$A$2:$A$20,0))&"–"&INDEX(Bloques!$E$2:$E$20,MATCH($F26,Bloques!$A$2:$A$20,0)) -> 5–6 | L26: =INDEX(Bloques!$F$2:$F$20,MATCH($F26,Bloques!$A$2:$A$20,0))&"–"&INDEX(Bloques!$G$2:$G$20,MATCH($F26,Bloques!$A$2:$A$20,0)) -> 90–100 | M26: =INDEX(Bloques!$J$2:$J$20,MATCH($F26,Bloques!$A$2:$A$20,0))&"–"&INDEX(Bloques!$K$2:$K$20,MATCH($F26,Bloques!$A$2:$A$20,0)) -> 90–100
A27: =B27&" "&C27&"′" -> Continuo 60′ | B27: Continuo | C27: 60 | D27: 8 | E27: Calma | F27: CLM | G27: =INDEX(Bloques!$B$2:$B$20,MATCH($F27,Bloques!$A$2:$A$20,0)) -> Vuelta a la calma | H27: 10 | I27: =I26+H26 -> 50 | J27: =INDEX(Bloques!$C$2:$C$20,MATCH($F27,Bloques!$A$2:$A$20,0)) -> Sentado | K27: =INDEX(Bloques!$D$2:$D$20,MATCH($F27,Bloques!$A$2:$A$20,0))&"–"&INDEX(Bloques!$E$2:$E$20,MATCH($F27,Bloques!$A$2:$A$20,0)) -> 1–2 | L27: =INDEX(Bloques!$F$2:$F$20,MATCH($F27,Bloques!$A$2:$A$20,0))&"–"&INDEX(Bloques!$G$2:$G$20,MATCH($F27,Bloques!$A$2:$A$20,0)) -> 70–90 | M27: =INDEX(Bloques!$J$2:$J$20,MATCH($F27,Bloques!$A$2:$A$20,0))&"–"&INDEX(Bloques!$K$2:$K$20,MATCH($F27,Bloques!$A$2:$A$20,0)) -> 70–90
A28: =B28&" "&C28&"′" -> Progresivo 15′ | B28: Progresivo | C28: 15 | D28: 1 | E28: Calentamiento | F28: CAL | G28: =INDEX(Bloques!$B$2:$B$20,MATCH($F28,Bloques!$A$2:$A$20,0)) -> Calentamiento | H28: 4 | I28: 0 | J28: =INDEX(Bloques!$C$2:$C$20,MATCH($F28,Bloques!$A$2:$A$20,0)) -> Sentado | K28: =INDEX(Bloques!$D$2:$D$20,MATCH($F28,Bloques!$A$2:$A$20,0))&"–"&INDEX(Bloques!$E$2:$E$20,MATCH($F28,Bloques!$A$2:$A$20,0)) -> 2–3 | L28: =INDEX(Bloques!$F$2:$F$20,MATCH($F28,Bloques!$A$2:$A$20,0))&"–"&INDEX(Bloques!$G$2:$G$20,MATCH($F28,Bloques!$A$2:$A$20,0)) -> 85–95 | M28: =INDEX(Bloques!$J$2:$J$20,MATCH($F28,Bloques!$A$2:$A$20,0))&"–"&INDEX(Bloques!$K$2:$K$20,MATCH($F28,Bloques!$A$2:$A$20,0)) -> 85–95
A29: =B29&" "&C29&"′" -> Progresivo 15′ | B29: Progresivo | C29: 15 | D29: 2 | E29: Escalón 1 | F29: TEM | G29: =INDEX(Bloques!$B$2:$B$20,MATCH($F29,Bloques!$A$2:$A$20,0)) -> Tempo | H29: 4 | I29: =I28+H28 -> 4 | J29: =INDEX(Bloques!$C$2:$C$20,MATCH($F29,Bloques!$A$2:$A$20,0)) -> Sentado | K29: =INDEX(Bloques!$D$2:$D$20,MATCH($F29,Bloques!$A$2:$A$20,0))&"–"&INDEX(Bloques!$E$2:$E$20,MATCH($F29,Bloques!$A$2:$A$20,0)) -> 5–6 | L29: =INDEX(Bloques!$F$2:$F$20,MATCH($F29,Bloques!$A$2:$A$20,0))&"–"&INDEX(Bloques!$G$2:$G$20,MATCH($F29,Bloques!$A$2:$A$20,0)) -> 90–100 | M29: =INDEX(Bloques!$J$2:$J$20,MATCH($F29,Bloques!$A$2:$A$20,0))&"–"&INDEX(Bloques!$K$2:$K$20,MATCH($F29,Bloques!$A$2:$A$20,0)) -> 90–100 | N29: Sin escalón de llano: el calentamiento hace de base
A30: =B30&" "&C30&"′" -> Progresivo 15′ | B30: Progresivo | C30: 15 | D30: 3 | E30: Escalón 2 | F30: SUS | G30: =INDEX(Bloques!$B$2:$B$20,MATCH($F30,Bloques!$A$2:$A$20,0)) -> Subida sentado | H30: 4 | I30: =I29+H29 -> 8 | J30: =INDEX(Bloques!$C$2:$C$20,MATCH($F30,Bloques!$A$2:$A$20,0)) -> Sentado | K30: =INDEX(Bloques!$D$2:$D$20,MATCH($F30,Bloques!$A$2:$A$20,0))&"–"&INDEX(Bloques!$E$2:$E$20,MATCH($F30,Bloques!$A$2:$A$20,0)) -> 6–7 | L30: =INDEX(Bloques!$F$2:$F$20,MATCH($F30,Bloques!$A$2:$A$20,0))&"–"&INDEX(Bloques!$G$2:$G$20,MATCH($F30,Bloques!$A$2:$A$20,0)) -> 70–80 | M30: =INDEX(Bloques!$J$2:$J$20,MATCH($F30,Bloques!$A$2:$A$20,0))&"–"&INDEX(Bloques!$K$2:$K$20,MATCH($F30,Bloques!$A$2:$A$20,0)) -> 140–160
A31: =B31&" "&C31&"′" -> Progresivo 15′ | B31: Progresivo | C31: 15 | D31: 4 | E31: Calma | F31: CLM | G31: =INDEX(Bloques!$B$2:$B$20,MATCH($F31,Bloques!$A$2:$A$20,0)) -> Vuelta a la calma | H31: 3 | I31: =I30+H30 -> 12 | J31: =INDEX(Bloques!$C$2:$C$20,MATCH($F31,Bloques!$A$2:$A$20,0)) -> Sentado | K31: =INDEX(Bloques!$D$2:$D$20,MATCH($F31,Bloques!$A$2:$A$20,0))&"–"&INDEX(Bloques!$E$2:$E$20,MATCH($F31,Bloques!$A$2:$A$20,0)) -> 1–2 | L31: =INDEX(Bloques!$F$2:$F$20,MATCH($F31,Bloques!$A$2:$A$20,0))&"–"&INDEX(Bloques!$G$2:$G$20,MATCH($F31,Bloques!$A$2:$A$20,0)) -> 70–90 | M31: =INDEX(Bloques!$J$2:$J$20,MATCH($F31,Bloques!$A$2:$A$20,0))&"–"&INDEX(Bloques!$K$2:$K$20,MATCH($F31,Bloques!$A$2:$A$20,0)) -> 70–90
A32: =B32&" "&C32&"′" -> Progresivo 30′ | B32: Progresivo | C32: 30 | D32: 1 | E32: Calentamiento | F32: CAL | G32: =INDEX(Bloques!$B$2:$B$20,MATCH($F32,Bloques!$A$2:$A$20,0)) -> Calentamiento | H32: 5 | I32: 0 | J32: =INDEX(Bloques!$C$2:$C$20,MATCH($F32,Bloques!$A$2:$A$20,0)) -> Sentado | K32: =INDEX(Bloques!$D$2:$D$20,MATCH($F32,Bloques!$A$2:$A$20,0))&"–"&INDEX(Bloques!$E$2:$E$20,MATCH($F32,Bloques!$A$2:$A$20,0)) -> 2–3 | L32: =INDEX(Bloques!$F$2:$F$20,MATCH($F32,Bloques!$A$2:$A$20,0))&"–"&INDEX(Bloques!$G$2:$G$20,MATCH($F32,Bloques!$A$2:$A$20,0)) -> 85–95 | M32: =INDEX(Bloques!$J$2:$J$20,MATCH($F32,Bloques!$A$2:$A$20,0))&"–"&INDEX(Bloques!$K$2:$K$20,MATCH($F32,Bloques!$A$2:$A$20,0)) -> 85–95
A33: =B33&" "&C33&"′" -> Progresivo 30′ | B33: Progresivo | C33: 30 | D33: 2 | E33: Escalón 1 | F33: LLA | G33: =INDEX(Bloques!$B$2:$B$20,MATCH($F33,Bloques!$A$2:$A$20,0)) -> Llano | H33: 5 | I33: =I32+H32 -> 5 | J33: =INDEX(Bloques!$C$2:$C$20,MATCH($F33,Bloques!$A$2:$A$20,0)) -> Sentado | K33: =INDEX(Bloques!$D$2:$D$20,MATCH($F33,Bloques!$A$2:$A$20,0))&"–"&INDEX(Bloques!$E$2:$E$20,MATCH($F33,Bloques!$A$2:$A$20,0)) -> 3–4 | L33: =INDEX(Bloques!$F$2:$F$20,MATCH($F33,Bloques!$A$2:$A$20,0))&"–"&INDEX(Bloques!$G$2:$G$20,MATCH($F33,Bloques!$A$2:$A$20,0)) -> 90–100 | M33: =INDEX(Bloques!$J$2:$J$20,MATCH($F33,Bloques!$A$2:$A$20,0))&"–"&INDEX(Bloques!$K$2:$K$20,MATCH($F33,Bloques!$A$2:$A$20,0)) -> 90–100
A34: =B34&" "&C34&"′" -> Progresivo 30′ | B34: Progresivo | C34: 30 | D34: 3 | E34: Escalón 2 | F34: TEM | G34: =INDEX(Bloques!$B$2:$B$20,MATCH($F34,Bloques!$A$2:$A$20,0)) -> Tempo | H34: 5 | I34: =I33+H33 -> 10 | J34: =INDEX(Bloques!$C$2:$C$20,MATCH($F34,Bloques!$A$2:$A$20,0)) -> Sentado | K34: =INDEX(Bloques!$D$2:$D$20,MATCH($F34,Bloques!$A$2:$A$20,0))&"–"&INDEX(Bloques!$E$2:$E$20,MATCH($F34,Bloques!$A$2:$A$20,0)) -> 5–6 | L34: =INDEX(Bloques!$F$2:$F$20,MATCH($F34,Bloques!$A$2:$A$20,0))&"–"&INDEX(Bloques!$G$2:$G$20,MATCH($F34,Bloques!$A$2:$A$20,0)) -> 90–100 | M34: =INDEX(Bloques!$J$2:$J$20,MATCH($F34,Bloques!$A$2:$A$20,0))&"–"&INDEX(Bloques!$K$2:$K$20,MATCH($F34,Bloques!$A$2:$A$20,0)) -> 90–100
A35: =B35&" "&C35&"′" -> Progresivo 30′ | B35: Progresivo | C35: 30 | D35: 4 | E35: Escalón 3 | F35: SUS | G35: =INDEX(Bloques!$B$2:$B$20,MATCH($F35,Bloques!$A$2:$A$20,0)) -> Subida sentado | H35: 5 | I35: =I34+H34 -> 15 | J35: =INDEX(Bloques!$C$2:$C$20,MATCH($F35,Bloques!$A$2:$A$20,0)) -> Sentado | K35: =INDEX(Bloques!$D$2:$D$20,MATCH($F35,Bloques!$A$2:$A$20,0))&"–"&INDEX(Bloques!$E$2:$E$20,MATCH($F35,Bloques!$A$2:$A$20,0)) -> 6–7 | L35: =INDEX(Bloques!$F$2:$F$20,MATCH($F35,Bloques!$A$2:$A$20,0))&"–"&INDEX(Bloques!$G$2:$G$20,MATCH($F35,Bloques!$A$2:$A$20,0)) -> 70–80 | M35: =INDEX(Bloques!$J$2:$J$20,MATCH($F35,Bloques!$A$2:$A$20,0))&"–"&INDEX(Bloques!$K$2:$K$20,MATCH($F35,Bloques!$A$2:$A$20,0)) -> 140–160
A36: =B36&" "&C36&"′" -> Progresivo 30′ | B36: Progresivo | C36: 30 | D36: 5 | E36: Escalón 4 | F36: SUP | G36: =INDEX(Bloques!$B$2:$B$20,MATCH($F36,Bloques!$A$2:$A$20,0)) -> Subida de pie | H36: 4 | I36: =I35+H35 -> 20 | J36: =INDEX(Bloques!$C$2:$C$20,MATCH($F36,Bloques!$A$2:$A$20,0)) -> De pie | K36: =INDEX(Bloques!$D$2:$D$20,MATCH($F36,Bloques!$A$2:$A$20,0))&"–"&INDEX(Bloques!$E$2:$E$20,MATCH($F36,Bloques!$A$2:$A$20,0)) -> 7–8 | L36: =INDEX(Bloques!$F$2:$F$20,MATCH($F36,Bloques!$A$2:$A$20,0))&"–"&INDEX(Bloques!$G$2:$G$20,MATCH($F36,Bloques!$A$2:$A$20,0)) -> 60–75 | M36: =INDEX(Bloques!$J$2:$J$20,MATCH($F36,Bloques!$A$2:$A$20,0))&"–"&INDEX(Bloques!$K$2:$K$20,MATCH($F36,Bloques!$A$2:$A$20,0)) -> 120–150
A37: =B37&" "&C37&"′" -> Progresivo 30′ | B37: Progresivo | C37: 30 | D37: 6 | E37: Calma | F37: CLM | G37: =INDEX(Bloques!$B$2:$B$20,MATCH($F37,Bloques!$A$2:$A$20,0)) -> Vuelta a la calma | H37: 6 | I37: =I36+H36 -> 24 | J37: =INDEX(Bloques!$C$2:$C$20,MATCH($F37,Bloques!$A$2:$A$20,0)) -> Sentado | K37: =INDEX(Bloques!$D$2:$D$20,MATCH($F37,Bloques!$A$2:$A$20,0))&"–"&INDEX(Bloques!$E$2:$E$20,MATCH($F37,Bloques!$A$2:$A$20,0)) -> 1–2 | L37: =INDEX(Bloques!$F$2:$F$20,MATCH($F37,Bloques!$A$2:$A$20,0))&"–"&INDEX(Bloques!$G$2:$G$20,MATCH($F37,Bloques!$A$2:$A$20,0)) -> 70–90 | M37: =INDEX(Bloques!$J$2:$J$20,MATCH($F37,Bloques!$A$2:$A$20,0))&"–"&INDEX(Bloques!$K$2:$K$20,MATCH($F37,Bloques!$A$2:$A$20,0)) -> 70–90
A38: =B38&" "&C38&"′" -> Progresivo 45′ | B38: Progresivo | C38: 45 | D38: 1 | E38: Calentamiento | F38: CAL | G38: =INDEX(Bloques!$B$2:$B$20,MATCH($F38,Bloques!$A$2:$A$20,0)) -> Calentamiento | H38: 5 | I38: 0 | J38: =INDEX(Bloques!$C$2:$C$20,MATCH($F38,Bloques!$A$2:$A$20,0)) -> Sentado | K38: =INDEX(Bloques!$D$2:$D$20,MATCH($F38,Bloques!$A$2:$A$20,0))&"–"&INDEX(Bloques!$E$2:$E$20,MATCH($F38,Bloques!$A$2:$A$20,0)) -> 2–3 | L38: =INDEX(Bloques!$F$2:$F$20,MATCH($F38,Bloques!$A$2:$A$20,0))&"–"&INDEX(Bloques!$G$2:$G$20,MATCH($F38,Bloques!$A$2:$A$20,0)) -> 85–95 | M38: =INDEX(Bloques!$J$2:$J$20,MATCH($F38,Bloques!$A$2:$A$20,0))&"–"&INDEX(Bloques!$K$2:$K$20,MATCH($F38,Bloques!$A$2:$A$20,0)) -> 85–95
A39: =B39&" "&C39&"′" -> Progresivo 45′ | B39: Progresivo | C39: 45 | D39: 2 | E39: Escalón 1 | F39: LLA | G39: =INDEX(Bloques!$B$2:$B$20,MATCH($F39,Bloques!$A$2:$A$20,0)) -> Llano | H39: 7 | I39: =I38+H38 -> 5 | J39: =INDEX(Bloques!$C$2:$C$20,MATCH($F39,Bloques!$A$2:$A$20,0)) -> Sentado | K39: =INDEX(Bloques!$D$2:$D$20,MATCH($F39,Bloques!$A$2:$A$20,0))&"–"&INDEX(Bloques!$E$2:$E$20,MATCH($F39,Bloques!$A$2:$A$20,0)) -> 3–4 | L39: =INDEX(Bloques!$F$2:$F$20,MATCH($F39,Bloques!$A$2:$A$20,0))&"–"&INDEX(Bloques!$G$2:$G$20,MATCH($F39,Bloques!$A$2:$A$20,0)) -> 90–100 | M39: =INDEX(Bloques!$J$2:$J$20,MATCH($F39,Bloques!$A$2:$A$20,0))&"–"&INDEX(Bloques!$K$2:$K$20,MATCH($F39,Bloques!$A$2:$A$20,0)) -> 90–100
A40: =B40&" "&C40&"′" -> Progresivo 45′ | B40: Progresivo | C40: 45 | D40: 3 | E40: Escalón 2 | F40: TEM | G40: =INDEX(Bloques!$B$2:$B$20,MATCH($F40,Bloques!$A$2:$A$20,0)) -> Tempo | H40: 8 | I40: =I39+H39 -> 12 | J40: =INDEX(Bloques!$C$2:$C$20,MATCH($F40,Bloques!$A$2:$A$20,0)) -> Sentado | K40: =INDEX(Bloques!$D$2:$D$20,MATCH($F40,Bloques!$A$2:$A$20,0))&"–"&INDEX(Bloques!$E$2:$E$20,MATCH($F40,Bloques!$A$2:$A$20,0)) -> 5–6 | L40: =INDEX(Bloques!$F$2:$F$20,MATCH($F40,Bloques!$A$2:$A$20,0))&"–"&INDEX(Bloques!$G$2:$G$20,MATCH($F40,Bloques!$A$2:$A$20,0)) -> 90–100 | M40: =INDEX(Bloques!$J$2:$J$20,MATCH($F40,Bloques!$A$2:$A$20,0))&"–"&INDEX(Bloques!$K$2:$K$20,MATCH($F40,Bloques!$A$2:$A$20,0)) -> 90–100
...
